Workbook

Sheet 1-Instructions
C3: Ground Crossing Strategic Risk Assessment Tool
C5: Developed from the Handbook for public health capacity-building at ground crossings and cross-border collaboration
C6: https://www.who.int/publications/i/item/handbook-for-public-health-capacity-building-at-ground-crossings-and-cross-border-collaboration
C8: How to use this tool. Note: - Information included in the sheet are used to guide the assessment in order to achieve the desired outcomes. - The number of the hazard is limited to 10 in the tool but can be expanded. However, this action will trigger adjustment of the tool.
C9: • Step 1. Assemble a strategic risk assessment team. The knowledge and expertise of the team will greatly influence the quality of the strategic risk assessment process. Additional expertise can be brought in at any time.
C10: • Step 2. Use the Hazard Assessment Sheet to: Identify emerging hazards, known hazards or public health concerns associated with prioritized ground crossings and write the name of each identified hazard in the appropriate range B14 to K14.
C11: • Step 3. For each identified hazard: • Use the Vulnerability Assessment Sheet to assess the vulnerability of the identified hazard. For example, range C9 to E16 provides the area to evaluate the exposure level of Hazard 1 by responding to five questions that generate a score which leads to classification of the vulnerability level of Hazard 1 that appears in cell E104. The score is populated directly in the scorecard sheet (cell D9). • Use the Severity Assessment Sheet to assess the severity of the identified hazard. For example, range B6 to D11 provides the area to evaluate the severity level of Hazard 1 by responding to three questions that generate a score which leads to classification of the severity level of Hazard 1 that appears in cell C81. The score is populated directly in the scorecard sheet (cell D10). • Use the Capacity Assessment Sheet to assess the capacity of the ground crossing. A series of guiding questions is provided in the range C7 to E84 to assist in the evaluation of existing coping capacities that should be used to manage potential hazards. All applicable questions in the tool are to be answered as Yes/Completed, Maybe/In Progress, or No. The overall coping capacity score (1–5) is populated in the range D96 to E97, including the level of the capacity. The overall score is populated directly in the scorecard sheet (range E11 to M11).
C12: • Step 4. The scorecard sheet to assign a level of risk in order to populate the risk matrix. • Step 4.a Use the Likelihood Assessment Sheet to assess the likelihood of the identified hazard. For example, range B9 to D16 provides the areas to evaluate the likelihood level of Hazard 1 by responding to five questions that generate a score leading to classification of the likelihood level of Hazard 1 that appears in cell D104. The score is populated directly in the scorecard sheet (cell D17). • Step 4.b Range C7 to M14 of the Scorecard Sheet is linked to the score of the vulnerability, severity and capacity assessment sheets. The formula (Impact = (vulnerability + severity + coping capacity)/3) in the scorecard sheet generates the impact value and the level of each hazard identified in the range C12 to M14. Range C17 to M18 of the Scorecard Sheet is linked to the score of the likelihood assessment sheet to facilitate the reading of the risk level of each hazard (Range C31 to I127) guided by the risk matrix inserted in the range C21 to I27.
C13: • Step 5. Risk mitigation: Range C13 to M13 in the Risk Mitigation Sheet provides the opportunity to write the mitigation measures for each identified hazard adopted following the assessment.

Sheet 2-Ground Crossing ID
B2: Date of the Assessment
B4: Point of Entry name | C4: Port Sudan International Airport
B5: Address | C5: Sudan Republic – Red sea state Port Sudan international airport
B6: Telephone | C6: [+249311823507]
B7: Fax | C7: P.O BOX 487
B8: Email | C8: portsudanairport@hotmail.com
B9: Web address | C9: AERODROME OPERATOR Sudan Airports Co. Ltd (SAC )
B10: GPS code | C10: LOCATION : Sudan – Red sea state
B11: Designated (Yes/No) | C11: NO
B12: Category (1, 2 or 3 according to WHO categorization)
B14: Contact details of Competent Authority agency بيانات الاتصال بالجهة المختصة | C14: National level | D14: Intermediate level | E14: Local level | F14: Ground crossing level
B15: Address
B16: Telephone
B17: Fax
B18: Email
B19: Web address
B20: GPS code
B21: Contact person details | C21: National level | D21: Intermediate level | E21: Local level | F21: Ground crossing level
B22: Name
B23: Telephone
B24: Email
B26: Contact details of Health Competent Authority agency بيانات الاتصال بالجهة المختصة بالصحة | C26: National level | D26: Intermediate level | E26: Local level | F26: Ground crossing level
B27: Address | C27: Dr.ELFATIH RABEI ABDALLA | D27: Dr.AHMED MOHAMMED OSMAN DARREER | E27: ALI MOHAMED NOR ABOMOHAMED
B28: Telephone | C28: [+249912508725] | D28: [+249912295148] | E28: [+249912488093]
B29: Fax
B30: Email | C30: ElfatihRabie@gmail.com | D30: darreer@gmail.com | E30: airportportsudan@gmail.com
B31: Web address | C31: ElfatihRabie@gmail.com | D31: darreer.wordpress.com | E31: airportportsudan@gmail.com
B32: GPS code | C32: LOCATION : Sudan – Red sea state | D32: LOCATION : Sudan – Red sea state | E32: LOCATION : Sudan – Red sea state
B33: Contact Person details | C33: National level | D33: Intermediate level | E33: Local level | F33: Ground crossing level
B34: Name | C34: TAHANI ADAM MAHDI YOSIF | D34: MUSTAFA MUSA EISA MUSA | E34: ALI MOHAMED NOR ABOMOHAMED
B35: Telephone | C35: [+249911241181] | D35: [+249915622034] | E35: [+249912488093]
B36: Email | C36: tahanydm94@gmail.com | D36: mustafaanshish@gmail.com | E36: airportportsudan@gmail.com

Sheet 3-Hazard Assessment
A2: Listing of all existing or emerging hazards which – on the basis of public health event data – have the potential to cause a health emergency and that may have an impact on the ground crossing. Hazards may be biological, chemical, physical or radiological. قائمة بجميع المخاطر الحالية أو الناشئة التي - بناءً على بيانات الأحداث الصحية العامة - لديها القدرة على التسبب في حالة طوارئ صحية وقد يكون لها تأثير على عبور الطريق البري. قد تكون المخاطر بيولوجية أو كيميائية أو فيزيائية أو إشعاعية.
A3: 1. Assess burden of diseases factors. Review records such as: تقييم عوامل عبء الأمراض. مراجعة سجلات مثل
A4: · epidemiological studies; دراسات الاوبئة
A5: · health-care system data; بيانات نظام الرعاية الصحية
A6: · clinical data; البيانات السريرية
A7: · existing mapping data on the distribution of high-consequence communicable disease; and بيانات رسم الخرائط الحالية حول توزيع الأمراض المعدية ذات العواقب الوخيمة؛
A8: · surveillance data and trends.بيانات الترصد و الميل لحدوث الاوبئة
A9: 2. Evaluate data and linkages between available public health data, literature reviews, studies and academic/research information. تقييم البيانات والارتباطات بين بيانات الصحة العامة المتاحة ومراجعات الأدبيات والدراسات والمعلومات الأكاديمية / البحثية.
A10: 3. Review immunization registries, vital statistics, and note any disparities. قم بمراجعة سجلات التحصين والإحصاءات الحيوية ولاحظ أي فوارق.
A11: 4. Identify type of hazard. تحديد نوع الخطر
B13: HAZARD 1 | C13: HAZARD 2 | D13: HAZARD 3 | E13: HAZARD 4 | F13: HAZARD 5 | G13: HAZARD 6 | H13: HAZARD 7 | I13: HAZARD 8 | J13: HAZARD 9 | K13: HAZARD 10
A14: EXISTING AND EMERGING HAZARD NAME تسمية الخطر | B14: Dengue | C14: Cholera | D14: Malaria | E14: VHF | F14: Covid-19 | G14: Influenza | H14: Mass Casualities | I14: Chemical | J14: Radiological | K14: Physical

Sheet 4- Vulnerabilty Assessment
C4: Exposure: التعرض: بالنسبة لكل خطر محتمل (بيولوجي أو كيميائي أو فيزيائي أو إشعاعي)، قم بتقييم التعرضات المحتملة للأفراد والسكان للمخاطر المحددة في تقييم المخاطر. بالتشاور مع الخبراء المحليين وأصحاب المصلحة والمصادر المحلية للمعلومات، يجب على فريق تقييم المخاطر الاستراتيجية استخدام سلسلة من العوامل التوجيهية وأي معلومات أخرى ذات صلة محلية حول الخطر لتعيين درجة تعرض تتراوح من 1 إلى 5 للخطر. ستكون الدرجة ذاتية وستستند إلى أفضل المعلومات المتوفرة والدقيقة والحديثة For each possible hazard (biological, chemical, physical or radiological), evaluate the potential exposures of individuals and populations to the hazards identified in the hazard assessment. In consultation with local experts, stakeholders and local sources of information, the strategic risk assessment team should use a series of guiding factors and any other locally relevant information about the hazard to assign an exposure score of 1 to 5 to the hazard. The score will be subjective and will be based on the best available, accurate and recent information. The exposure score will be used to determine the level of impact of the hazard.
C5: Guiding factors to take into consideration when determining exposure:
C6: • Identify geographical areas that are likely to be affected by the health consequences and distribution factors (e.g. the number and location of chemical plants and the chemicals they use). • تحديد المناطق الجغرافية التي من المرجح أن تتأثر بالعواقب الصحية وعوامل التوزيع (على سبيل المثال عدد وموقع المصانع الكيميائية والمواد الكيميائية التي تستخدمها). • Identify and estimate the number of exposed persons at a ground crossing who may contract a disease or who could become infected due to lack of immunity (i.e. the susceptible population at risk) in the case of a biological hazard. تحديد وتقدير عدد الأشخاص المعرضين عند المعبر البري والذين قد يصابون بالمرض أو الذين يمكن أن يصابوا بالعدوى بسبب نقص المناعة (أي السكان المعرضين للخطر) في حالة وجود خطر بيولوجي. • Identify and estimate the size and density of communities near the ground crossing or along associated transit routes. تحديد وتقدير حجم وكثافة المجتمعات القريبة من المعبر البري أو على طول طرق العبور المرتبطة به. • Identify and estimate the number of people living in the high-risk area of the ground crossing and adjacent border communities in the case of a chemical or radiological hazard. Note: تحديد وتقدير عدد الأشخاص الذين يعيشون في المنطقة شديدة الخطورة للمعبر البري والمجتمعات الحدودية المجاورة في حالة وجود خطر كيميائي أو إشعاعي. ملحوظة • duration of exposure; and مدة التعرض • risk of exposure to chemical or radiological substances, or vulnerability to natural disasters. خطر التعرض للمواد الكيميائية أو الإشعاعية، أو التعرض للكوارث الطبيعي • Identify the modality of interactions between communities on either side of a ground crossing with travellers, cargoes and conveyances moving across borders. التعرف على طريقة التفاعل بين المجتمعات على جانبي المعبر البري مع المسافرين والبضائع ووسائل النقل التي تتحرك عبر الحدود. The assessment team should use the information collected to answer, for each possible hazard, the five questions that are below. Each question should be answered by either YES or NO. YES scores 1 and NO scores 0. يجب على فريق التقييم استخدام المعلومات التي تم جمعها للإجابة عن الأسئلة الخمسة أدناه لكل خطر محتمل. يجب الإجابة على كل سؤال إما بنعم أو لا. تحصل الإجابة بنعم على 1 وتحصل الإجابة بلا على 0. Click on the drop-down tab in the cell in front of the question to choose the answer. Following this action, the score will appear in the next cell on the same line. When all five questions have been answered, the total vulnerability score for the identified hazard will appear in the cell next to the "TOTAL SCORE" cell. This score will also appear on line 103 while the vulnerability level will appear on line 104 under the column assigned to the identified hazard. انقر فوق علامة التبويب المنسدلة في الخلية الموجودة أمام السؤال لاختيار الإجابة. بعد هذا الإجراء، ستظهر النتيجة في الخلية التالية على نفس السطر. عندما تتم الإجابة على جميع الأسئلة الخمسة، ستظهر درجة الضعف الإجمالية للخطر المحدد في الخلية بجوار خلية ""النتيجة الإجمالية"". ستظهر هذه النتيجة أيضًا على السطر 103 بينما سيظهر مستوى الضعف على السطر 104 أسفل العمود المخصص للخطر المحدد. The assigned score from 1 to 5 would be as follows: ستكون النتيجة المخصصة من 1 إلى 5 على النحو التالي: 1. Very low exposure تعريض منخفض جدا 2 2. Low exposure تعريض منخفض 3 3. Moderate exposure تعرض متوسط 4 4. High exposure تعرض عالي 5 5. Very high exposure تعرض عالي جدا
C9: HAZARD 1 | D9: ='3-Hazard Assessment'!B14 -> Dengue
C10: QUESTIONS | D10: YES / NO | E10: Score
C11: Are the hight risk area likely to be affected by the consequence of the identify health hazard identified? هل من المرجح أن تتأثر المنطقة ذات الخطورة العالية بعواقب تحديد المخاطر الصحية التي تم تحديدها؟ | D11: Yes | E11: =IF(D11="YES",1,0) -> 1
C12: Is a large number of people could contact a disease or get infected due to lack of immunity (i.e. the susceptible population at risk) in case of a biological hazard at the ground crossing? | D12: Yes | E12: =IF(D12="YES",1,0) -> 1
C13: Is the population density in adjacent community area high? | D13: Yes | E13: =IF(D13="YES",1,0) -> 1
C14: Are people living in the high-risk area of ground crossing and adjacent border communities? | D14: Yes | E14: =IF(D14="YES",1,0) -> 1
C15: Are the modalities of interactions between ommunities on either side of a ground crossing with travellers is high? | D15: Yes | E15: =IF(D15="YES",1,0) -> 1
C16: TOTAL SCORE | E16: =SUM(E11:E15) -> 5
C18: HAZARD 2 | D18: ='3-Hazard Assessment'!C14 -> Cholera
C19: QUESTIONS | D19: YES / NO/NA | E19: Score
C20: Are the high-risk areas likely to be affected by the consequences of the identified health hazard? هل من المحتمل أن تتأثر المناطق المعرضة للخطر بعواقب المخاطر الصحية التي تم تحديدها؟ | D20: YES | E20: =IF(D20="YES",1,0) -> 1
C21: Could a large number of people contract a disease or become infected due to lack of immunity (i.e. the susceptible population at risk) in the case of a biological hazard at the ground crossing? هل يمكن أن يصاب عدد كبير من الأشخاص بمرض أو يصابون به بسبب نقص المناعة (أي السكان المعرضين للخطر) في حالة وجود خطر بيولوجي عند عبور الحدود البرية؟ | D21: YES | E21: =IF(D21="YES",1,0) -> 1
C22: Is the population density in adjacent community areas high? هل الكثافة السكانية في المناطق المجتمعية المجاورة عالية؟ | D22: YES | E22: =IF(D22="YES",1,0) -> 1
C23: Are large numbers of people living in the high-risk areas of the ground crossing and adjacent border communities? ل يعيش عدد كبير من الأشخاص في المناطق عالية الخطورة على الأرض ويعبرون المجتمعات الحدودية المجاورة | D23: YES | E23: =IF(D23="YES",1,0) -> 1
C24: Is there a high level of interaction between communities on either side of the ground crossing and travellers? "هل هناك مستوى عالٍ من التفاعل بين المجتمعات على جانبي معبر الحدود البري والمسافرين؟ | D24: YES | E24: =IF(D24="YES",1,0) -> 1
C25: TOTAL SCORE | E25: =SUM(E20:E24) -> 5
C27: HAZARD 3 | D27: ='3-Hazard Assessment'!D14 -> Malaria
C28: QUESTIONS | D28: YES / NO/NA | E28: Score
C29: Are the high-risk areas likely to be affected by the consequences of the identified health hazard? | D29: YES | E29: =IF(D29="YES",1,0) -> 1
C30: Could a large number of people contract a disease or become infected due to lack of immunity (i.e. the susceptible population at risk) in the case of a biological hazard at the ground crossing? | D30: YES | E30: =IF(D30="YES",1,0) -> 1
C31: Is the population density in adjacent community areas high? | D31: Yes | E31: =IF(D31="YES",1,0) -> 1
C32: Are large numbers of people living in the high-risk areas of the ground crossing and adjacent border communities? | D32: Yes | E32: =IF(D32="YES",1,0) -> 1
C33: Is there a high level of interaction between communities on either side of the ground crossing and travellers? | D33: Yes | E33: =IF(D33="YES",1,0) -> 1
C34: TOTAL SCORE | E34: =SUM(E29:E33) -> 5
C37: HAZARD 4 | D37: VHF
C38: QUESTIONS | D38: YES / NO/NA | E38: Score
C39: Are the high-risk areas likely to be affected by the consequences of the identified health hazard? | D39: YES | E39: =IF(D39="YES",1,0) -> 1
C40: Could a large number of people contract a disease or become infected due to lack of immunity (i.e. the susceptible population at risk) in the case of a biological hazard at the ground crossing? | D40: YES | E40: =IF(D40="YES",1,0) -> 1
C41: Is the population density in adjacent community areas high? | D41: YES | E41: =IF(D41="YES",1,0) -> 1
C42: Are large numbers of people living in the high-risk areas of the ground crossing and adjacent border communities? | D42: YES | E42: =IF(D42="YES",1,0) -> 1
C43: Is there a high level of interaction between communities on either side of the ground crossing and travellers? | D43: YES | E43: =IF(D43="YES",1,0) -> 1
C44: TOTAL SCORE | E44: =SUM(E39:E43) -> 5
C46: HAZARD 5 | D46: ='3-Hazard Assessment'!F14 -> Covid-19
C47: QUESTIONS | D47: YES / NO/NA | E47: Score
C48: Are the high-risk areas likely to be affected by the consequences of the identified health hazard? | D48: YES | E48: =IF(D48="YES",1,0) -> 1
C49: Could a large number of people contract a disease or become infected due to lack of immunity (i.e. the susceptible population at risk) in the case of a biological hazard at the ground crossing? | D49: NO | E49: =IF(D49="YES",1,0) -> 0
C50: Is the population density in adjacent community areas high? | D50: YES | E50: =IF(D50="YES",1,0) -> 1
...

Sheet 5- Severity Assessment 
B4: Exposure: For each possible hazard (biological, chemical, physical or radiological), evaluate the potential exposures of individuals and populations to the hazards identified in the hazard assessment. In consultation with local experts, stakeholders and local sources of information the strategic risk assessment team should use a series of guiding factors and any other locally relevant information about the hazard to assign an exposure score of 1 to 5 to the hazard. The score will be subjective and will be based on the best available, accurate and recent information on the following factors in order to support the severity assessment: لتعرض: بالنسبة لكل خطر محتمل (بيولوجي أو كيميائي أو فيزيائي أو إشعاعي)، قم بتقييم التعرضات المحتملة للأفراد والسكان للمخاطر المحددة في تقييم المخاطر. بالتشاور مع الخبراء المحليين وأصحاب المصلحة والمصادر المحلية للمعلومات، يجب على فريق تقييم المخاطر الاستراتيجية استخدام سلسلة من العوامل التوجيهية وأي معلومات أخرى ذات صلة محلية حول الخطر لتعيين درجة تعرض من 1 إلى 5 للخطر. ستكون الدرجة ذاتية وستستند إلى أفضل المعلومات المتوفرة والدقيقة والحديثة حول العوامل التالية من أجل دعم تقييم الخطورة: • seriousness of consequences (morbidity and mortality); • خطورة العواقب (المرض والوفيات)؛ • immune status factors of the exposed population; عوامل الحالة المناعية للسكان المعرضين؛ • vector-borne diseases and related factors (e.g. distribution, density, infectivity, seasonal variations) and/or animal hosts (density, prevalence, existing control programmes) along/across borders and travel routes that have an impact on the borders. الأمراض المنقولة بالنواقل والعوامل ذات الصلة (على سبيل المثال التوزيع والكثافة والقدرة على العدوى والاختلافات الموسمية) و/أو العوائل الحيوانية (الكثافة والانتشار وبرامج المكافحة الحالية) على طول/عبر الحدود وطرق السفر التي لها تأثير على الحدود. The exposure score will be used to determine the level of impact of the hazard. ستستخدم درجة التعرض لتحديد مستوى تأثير الخطر. The assessment team should use the information collected to answer, for each possible hazard, the three questions that are below. The first question should be answered by either YES or NO. YES scores 1 and NO scores 0. The second and third questions should be answered with “High”, “Medium” or “Low. “High” scores 2, “Medium” scores 1 and “Low” scores 0. يجب على فريق التقييم استخدام المعلومات التي تم جمعها للإجابة عن الأسئلة الثلاثة أدناه لكل خطر محتمل. يجب الإجابة على السؤال الأول إما بنعم أو لا. تحصل الإجابة بنعم على 1 وإجابة لا على 0. يجب الإجابة على السؤالين الثاني والثالث بـ "عالي" أو "متوسط" أو "منخفض". تحصل الإجابة بـ "عالي" على 2 وإجابة "متوسط" على 1 وإجابة "منخفض" على 0. Click on the drop-down tab in the cell in front of the question to choose the answer. Following this action, the score will appear in the next cell on the same line. When all three questions have been answered, the total severity score for the identified hazard will appear in the cell next to the "TOTAL SCORE" cell. This score will also appear on line 81 and the severity level will appear on line 82 under the column assigned to the identified hazard. انقر فوق علامة التبويب المنسدلة في الخلية أمام السؤال لاختيار الإجابة. بعد هذا الإجراء، ستظهر النتيجة في الخلية التالية على نفس السطر. عند الإجابة على الأسئلة الثلاثة، ستظهر الدرجة الإجمالية لشدة الخطر المحدد في الخلية بجوار خلية "الدرجة الإجمالية". ستظهر هذه الدرجة أيضًا على السطر 81 وسيظهر مستوى الشدة على السطر 82 أسفل العمود المخصص للخطر المحدد. On the basis of the severity value, the following scales can be used to rate assessed severity of the hazard: على أساس قيمة الخطورة، يمكن استخدام المقاييس التالية لتقييم الخطورة المقدرة للخطر: 1. Very low severity شدة منخفضة جدا 2. Low severity شدة منخفضة 3. Moderate severity شدة متوسطة 4. High severity شدة عالية 5. Very high severity شدة عالية جدا
B6: HAZARD 1 | C6: ='3-Hazard Assessment'!B14 -> Dengue
B7: QUESTIONS | C7: Yes / No (for the first question) High, Medium or Low (for the second and third questions) | D7: Score | J7: How is the immunity status among the exposed or infected population and travellers to the hazard ?
B8: Is the infectivity or contamination that is characteristic of the hazard at the ground crossing high? هل معدل العدوى أو التلوث الذي يميز الخطر عند معبر الأرض مرتفع؟ | C8: YES | D8: =IF(C8="YES",1,0) -> 1
B9: How frequent are the medium- and long-term consequences of exposure to the hazard or infection among the exposed or infected population and travellers? ما مدى تكرار العواقب متوسطة وطويلة الأمد الناجمة عن التعرض للخطر أو العدوى بين السكان المعرضين أو المصابين والمسافرين؟ | C9: Medium | D9: =IF(C9='Support sheet '!$E$25,2,IF(C9='Support sheet '!$E$26,1,IF(C9='Support sheet '!$E$27,0))) -> 1
B10: What is the extent of mortality among the exposed or infected population and travellers? ما هو حجم الوفيات بين السكان المعرضين أو المصابين والمسافرين؟ | C10: Medium | D10: =IF(C10='Support sheet '!$E$25,2,IF(C10='Support sheet '!$E$26,1,IF(C10='Support sheet '!$E$27,0))) -> 1
B11: TOTAL SCORE | D11: =SUM(D8:D10) -> 3
B13: HAZARD 2 | C13: ='3-Hazard Assessment'!C14 -> Cholera
B14: QUESTIONS | C14: Yes / No (for the first question) High, Medium or Low (for the second and third questions) | D14: Score
B15: Is the infectivity or contamination that is characteristic of the hazard at the ground crossing high? | C15: YES | D15: =IF(C15="YES",1,0) -> 1
B16: How frequent are the medium- and long-term consequences of exposure to the hazard or infection among the exposed or infected population and travellers? | C16: High | D16: =IF(C16='Support sheet '!$E$25,2,IF(C16='Support sheet '!$E$26,1,IF(C16='Support sheet '!$E$27,0))) -> 2
B17: What is the extent of mortality among the exposed or infected population and travellers? | C17: High | D17: =IF(C17='Support sheet '!$E$25,2,IF(C17='Support sheet '!$E$26,1,IF(C17='Support sheet '!$E$27,0))) -> 2
B18: TOTAL SCORE | D18: =SUM(D15:D17) -> 5
B20: HAZARD 3 | C20: ='3-Hazard Assessment'!D14 -> Malaria
B21: QUESTIONS | C21: Yes / No (for the first question) High, Medium or Low (for the second and third questions) | D21: Score
B22: Is the infectivity or contamination that is characteristic of the hazard at the ground crossing high? | C22: NO | D22: =IF(C22="YES",1,0) -> 0
B23: How frequent are the medium- and long-term consequences of exposure to the hazard or infection among the exposed or infected population and travellers? | C23: Medium | D23: =IF(C23='Support sheet '!$E$25,2,IF(C23='Support sheet '!$E$26,1,IF(C23='Support sheet '!$E$27,0))) -> 1
B24: What is the extent of mortality among the exposed or infected population and travellers? | C24: Medium | D24: =IF(C24='Support sheet '!$E$25,2,IF(C24='Support sheet '!$E$26,1,IF(C24='Support sheet '!$E$27,0))) -> 1
B25: TOTAL SCORE | D25: =SUM(D22:D24) -> 2
B27: HAZARD 4 | C27: ='3-Hazard Assessment'!E14 -> VHF
B28: QUESTIONS | C28: Yes / No (for the first question) High, Medium or Low (for the second and third questions) | D28: Score
B29: Is the infectivity or contamination that is characteristic of the hazard at the ground crossing high? | C29: YES | D29: =IF(C29="YES",1,0) -> 1
B30: How frequent are the medium- and long-term consequences of exposure to the hazard or infection among the exposed or infected population and travellers? | C30: Medium | D30: =IF(C30='Support sheet '!$E$25,2,IF(C30='Support sheet '!$E$26,1,IF(C30='Support sheet '!$E$27,0))) -> 1
B31: What is the extent of mortality among the exposed or infected population and travellers? | C31: Medium | D31: =IF(C31='Support sheet '!$E$25,2,IF(C31='Support sheet '!$E$26,1,IF(C31='Support sheet '!$E$27,0))) -> 1
B32: TOTAL SCORE | D32: =SUM(D29:D31) -> 3
B34: HAZARD 5 | C34: ='3-Hazard Assessment'!F14 -> Covid-19
B35: QUESTIONS | C35: Yes / No (for the first question) High, Medium or Low (for the second and third questions) | D35: Score
B36: Is the infectivity or contamination that is characteristic of the hazard at the ground crossing high? | C36: YES | D36: =IF(C36="YES",1,0) -> 1
B37: How frequent are the medium- and long-term consequences of exposure to the hazard or infection among the exposed or infected population and travellers? | C37: Medium | D37: =IF(C37='Support sheet '!$E$25,2,IF(C37='Support sheet '!$E$26,1,IF(C37='Support sheet '!$E$27,0))) -> 1
B38: What is the extent of mortality among the exposed or infected population and travellers? | C38: Low | D38: =IF(C38='Support sheet '!$E$25,2,IF(C38='Support sheet '!$E$26,1,IF(C38='Support sheet '!$E$27,0))) -> 0
B39: TOTAL SCORE | D39: =SUM(D36:D38) -> 2
B41: HAZARD 6 | C41: ='3-Hazard Assessment'!G14 -> Influenza
B42: QUESTIONS | C42: Yes / No (for the first question) High, Medium or Low (for the second and third questions) | D42: Score
B43: Is the infectivity or contamination that is characteristic of the hazard at the ground crossing high? | C43: YES | D43: =IF(C43="YES",1,0) -> 1
B44: How frequent are the medium- and long-term consequences of exposure to the hazard or infection among the exposed or infected population and travellers? | C44: Low | D44: =IF(C44='Support sheet '!$E$25,2,IF(C44='Support sheet '!$E$26,1,IF(C44='Support sheet '!$E$27,0))) -> 0
B45: What is the extent of mortality among the exposed or infected population and travellers? | C45: Low | D45: =IF(C45='Support sheet '!$E$25,2,IF(C45='Support sheet '!$E$26,1,IF(C45='Support sheet '!$E$27,0))) -> 0
B46: TOTAL SCORE | D46: =SUM(D43:D45) -> 1
B48: HAZARD 7 | C48: ='3-Hazard Assessment'!H14 -> Mass Casualities
B49: QUESTIONS | C49: Yes / No (for the first question) High, Medium or Low (for the second and third questions) | D49: Score
B50: Is the infectivity or contamination that is characteristic of the hazard at the ground crossing high? | C50: NO | D50: =IF(C50="YES",1,0) -> 0
...

Sheet  6-Capacity Assessment
C3: Coping capacities refer to the capabilities of the ground crossing and border region to cope with and manage potential hazards. The guiding questions in the table below are provided to assist in evaluating existing coping capacities that should be used to manage potential hazards. The 78 questions are to be answered as “Yes/Completed”, “Maybe/In Progress” or “No” in the table below. An answer of “Yes/Completed” scores 2, “Maybe/In Progress” scores 1, and “No” scores 0. تشير قدرات التأقلم إلى قدرات منطقة عبور الحدود البرية على التأقلم مع المخاطر المحتملة وإدارتها. تم توفير الأسئلة التوجيهية في الجدول أدناه للمساعدة في تقييم قدرات التأقلم الحالية التي يجب استخدامها لإدارة المخاطر المحتملة. يجب الإجابة على الأسئلة الـ 78 بـ "نعم / مكتمل" أو "ربما / قيد التنفيذ" أو "لا" في الجدول أدناه. إجابة "نعم / مكتمل" درجتان، و"ربما / قيد التنفيذ" درجة واحدة، و"لا" درجة 0 In answering these 61 questions, the highest possible score is 156 and the lowest is 0. To reduce this score to a scale of 5 (i.e. very high, high, partial, low, very low), 156 was divided by 5, giving 31 (rounded). A step value of 31 was established between 0 and 156, giving the intervals (0–31, 32–62, 63–93,94–124, 125–156). These are aligned to the value of 1–5 and assigned to the levels of coping capacity commensurate with the hazards. Thus 1 equates to very high (i.e. the necessary capacities commensurate to the hazards are in place) and 5 equates to very low (no capacities commensurate to the hazards are in place): عند الإجابة على هذه الأسئلة الـ 61، فإن أعلى درجة ممكنة هي 156 وأقلها هي 0. لتقليل هذه الدرجة إلى مقياس من 5 (أي مرتفع جدًا، مرتفع، جزئي، منخفض، منخفض جدًا)، تم تقسيم 156 على 5، مما يعطي 31 (تقريبًا). تم تحديد قيمة خطوة 31 بين 0 و156، مع إعطاء الفواصل الزمنية (0-31، 32-62، 63-93، 94-124، 125-156). تتماشى هذه القيم مع القيمة 1-5 وتُخصص لمستويات القدرة على التكيف المتناسبة مع المخاطر. وبالتالي فإن 1 تعادل عالية جدًا (أي أن القدرات اللازمة المتناسبة مع المخاطر موجودة) و5 تعادل منخفضة جدًا (لا توجد قدرات متناسبة مع المخاطر موجودة): 1. Very high: 125–156 عالي جدا 2. High: 94–124 عالي 3. Partial: 63–93 جزئ 4. Low: 32–62 منخفض 5. Very low: 0–31 منخفض جدا Click on the drop-down tab in the cell in front of the question to choose the answer. Following this action, the score will appear in the next cell on the same line. Once the 78 questions have been answered, the total capacity score will appear in the cell next to the "TOTAL SCORE" cell. This score will be reduced to the five scales; the final capacity score and level will appear respectively in cells E96 and E97. انقر فوق علامة التبويب المنسدلة في الخلية أمام السؤال لاختيار الإجابة. بعد هذا الإجراء، ستظهر النتيجة في الخلية التالية على نفس السطر. بمجرد الإجابة على الأسئلة الـ 78، ستظهر درجة القدرة الإجمالية في الخلية المجاورة لخلية "الدرجة الإجمالية". سيتم تقليص هذه الدرجة إلى المقاييس الخمسة؛ ستظهر درجة القدرة النهائية والمستوى على التوالي في الخليتين E96 وE97.
C6: Questions | D6: Yes/Completed Maybe/In Progress No | E6: Score | F6: Comments
B7: Communication التواصل | C7: Have any staff in the ground crossing been identified as focal points for communication with stakeholders هل تم تحديد أي موظفين في المعبر الأرضي كنقطة محورية للتواصل مع أصحاب المصلحة؟ | D7: Yes / Completed | E7: =IF(D7='Support sheet '!$B$35,2,IF(D7='Support sheet '!$B$36,1,IF(D7='Support sheet '!$B$37,0))) -> 2
C8: within the ground crossing (e.g. service providers, stakeholders, and medical facilities that provide public health services to the ground crossing)? داخل المعبر البري (على سبيل المثال مقدمي الخدمات وأصحاب المصلحة والمرافق الطبية التي تقدم خدمات الصحة العامة للمعبر البري)؟ | D8: Maybe / In progress | E8: =IF(D8='Support sheet '!$B$35,2,IF(D8='Support sheet '!$B$36,1,IF(D8='Support sheet '!$B$37,0))) -> 1
C9: Has public health information been provided by the ground crossing to travellers? هل تم توفير معلومات الصحة العامة للمسافرين من خلال المعبر البري؟ | D9: Maybe / In progress | E9: =IF(D9='Support sheet '!$B$35,2,IF(D9='Support sheet '!$B$36,1,IF(D9='Support sheet '!$B$37,0))) -> 1
C10: Has public health information been provided by point of entry to local communities adjacent to the ground crossing? هل تم توفير معلومات الصحة العامة عند نقطة الدخول إلى المجتمعات المحلية المجاورة للمعبر البري؟ | D10: No | E10: =IF(D10='Support sheet '!$B$35,2,IF(D10='Support sheet '!$B$36,1,IF(D10='Support sheet '!$B$37,0))) -> 0
C11: Has public health information been provided to the surveillance system by impacted local communities adjacent to the ground crossing ? هل تم توفير معلومات الصحة العامة لنظام المراقبة من قبل المجتمعات المحلية المتأثرة المجاورة لمعبر الأرض؟ | D11: No | E11: =IF(D11='Support sheet '!$B$35,2,IF(D11='Support sheet '!$B$36,1,IF(D11='Support sheet '!$B$37,0))) -> 0
C12: Has a communication mechanism been established to communicate health-related information from the ground crossing to neighbouring countries or regional disease surveillance networks? هل تم إنشاء آلية اتصال لتوصيل المعلومات المتعلقة بالصحة من المعابر البرية إلى الدول المجاورة أو شبكات مراقبة الأمراض الإقليمية؟ | D12: No | E12: =IF(D12='Support sheet '!$B$35,2,IF(D12='Support sheet '!$B$36,1,IF(D12='Support sheet '!$B$37,0))) -> 0
C13: Have communication mechanisms been established to communicate to all levels of government, policy-makers and stakeholders? هل تم إنشاء آليات التواصل للتواصل مع كافة مستويات الحكومة وصناع السياسات وأصحاب المصلحة؟ | D13: No | E13: =IF(D13='Support sheet '!$B$35,2,IF(D13='Support sheet '!$B$36,1,IF(D13='Support sheet '!$B$37,0))) -> 0
C14: Has an up-to-date emergency contact list of stakeholders been established for public health events management? هل تم إنشاء قائمة اتصال طارئة محدثة لأصحاب المصلحة لإدارة الأحداث الصحية العامة؟ | D14: No | E14: =IF(D14='Support sheet '!$B$35,2,IF(D14='Support sheet '!$B$36,1,IF(D14='Support sheet '!$B$37,0))) -> 0
B15: Surveillance التقصي | C15: Are standard case definitions for public health events under surveillance (e.g. diseases, symptoms) used at the ground crossing? هل يتم استخدام تعريفات الحالات القياسية للأحداث الصحية العامة الخاضعة للمراقبة (مثل الأمراض والأعراض) عند معبر الحدود البري؟ | D15: Yes / Completed | E15: =IF(D15='Support sheet '!$B$35,2,IF(D15='Support sheet '!$B$36,1,IF(D15='Support sheet '!$B$37,0))) -> 2
C16: the ground crossing? | D16: No | E16: =IF(D16='Support sheet '!$B$35,2,IF(D16='Support sheet '!$B$36,1,IF(D16='Support sheet '!$B$37,0))) -> 0
C17: Are standard operating procedures in place to identify suspect cases at the ground crossing? هل توجد إجراءات تشغيلية قياسية لتحديد الحالات المشتبه بها عند المعبر البري؟ | D17: No | E17: =IF(D17='Support sheet '!$B$35,2,IF(D17='Support sheet '!$B$36,1,IF(D17='Support sheet '!$B$37,0))) -> 0
C18: Are standard operating procedures in place to identify suspect cases within neighbouring communities? هل توجد إجراءات تشغيلية قياسية لتحديد الحالات المشتبه بها داخل المجتمعات المجاورة؟ | D18: No | E18: =IF(D18='Support sheet '!$B$35,2,IF(D18='Support sheet '!$B$36,1,IF(D18='Support sheet '!$B$37,0))) -> 0
C19: Does the surveillance system receive public health information from ground crossings, including the presence of ill or deceased travellers? هل يستقبل نظام المراقبة معلومات الصحة العامة من المعابر البرية، بما في ذلك وجود مسافرين مرضى أو متوفين؟ | D19: Yes / Completed | E19: =IF(D19='Support sheet '!$B$35,2,IF(D19='Support sheet '!$B$36,1,IF(D19='Support sheet '!$B$37,0))) -> 2
C20: Does the surveillance system receive environmental health information from ground crossings in relation to infection and contamination of food/water? هل يستقبل نظام المراقبة معلومات الصحة البيئية من المعابر البرية فيما يتعلق بالعدوى وتلوث الغذاء/المياه؟ | D20: No | E20: =IF(D20='Support sheet '!$B$35,2,IF(D20='Support sheet '!$B$36,1,IF(D20='Support sheet '!$B$37,0))) -> 0
C21: Does the surveillance system receive information in relation to vectors and reservoirs associated with vector-borne diseases? هل يتلقى نظام المراقبة معلومات تتعلق بالناقلات والخزانات المرتبطة بالأمراض التي ينقلها النواقل؟ | D21: No | E21: =IF(D21='Support sheet '!$B$35,2,IF(D21='Support sheet '!$B$36,1,IF(D21='Support sheet '!$B$37,0))) -> 0
C22: Does the surveillance system receive information in relation to chemical or radiological hazards? هل يتلقى نظام المراقبة معلومات تتعلق بالناقلات والخزانات المرتبطة بالأمراض التي ينقلها النواقل؟ | D22: Yes / Completed | E22: =IF(D22='Support sheet '!$B$35,2,IF(D22='Support sheet '!$B$36,1,IF(D22='Support sheet '!$B$37,0))) -> 2
C23: Have the reporting sites been established at the ground crossing? If so: هل تم إنشاء مواقع الإبلاغ عند المعبر البري؟ إذا كان الأمر كذلك: | D23: Yes / Completed | E23: =IF(D23='Support sheet '!$B$35,2,IF(D23='Support sheet '!$B$36,1,IF(D23='Support sheet '!$B$37,0))) -> 2
C24: Have the reporting mechanisms from the ground crossing to the national level been identified? هل تم تحديد آليات الإبلاغ من المعبر البري إلى المستوى الوطني؟ | D24: Yes / Completed | E24: =IF(D24='Support sheet '!$B$35,2,IF(D24='Support sheet '!$B$36,1,IF(D24='Support sheet '!$B$37,0))) -> 2
C25: Have the reporting mechanisms from the border community to the national level been identified? هل تم تحديد آليات الإبلاغ من مجتمع الحدود إلى المستوى الوطني؟ | D25: Yes / Completed | E25: =IF(D25='Support sheet '!$B$35,2,IF(D25='Support sheet '!$B$36,1,IF(D25='Support sheet '!$B$37,0))) -> 2
C26: Is information standardized when a public health event is reported by the ground crossing to the national surveillance system (i.e. is there a predefined list and standardized format for the variables to be reported)? هل يتم توحيد المعلومات عند الإبلاغ عن حدث صحي عام من قبل المعبر البري إلى نظام المراقبة الوطني (أي هل توجد قائمة محددة مسبقًا وتنسيق موحد للمتغيرات التي يجب الإبلاغ عنها)؟ | D26: No | E26: =IF(D26='Support sheet '!$B$35,2,IF(D26='Support sheet '!$B$36,1,IF(D26='Support sheet '!$B$37,0))) -> 0
C27: Have the staff of the ground crossing been trained in how to identify a potentially ill traveller? هل تم تدريب موظفي المعبر البري على كيفية تحديد المسافر المريض المحتمل؟ | D27: Yes / Completed | E27: =IF(D27='Support sheet '!$B$35,2,IF(D27='Support sheet '!$B$36,1,IF(D27='Support sheet '!$B$37,0))) -> 2
C28: Has a system been established between the national surveillance system and the ground crossing for management of case-related data (including contact-tracing)? هل يتم توحيد المعلومات عند الإبلاغ عن حدث صحي عام من قبل المعبر البري إلى نظام المراقبة الوطني (أي هل توجد قائمة محددة مسبقًا وتنسيق موحد للمتغيرات التي يجب الإبلاغ عنها)؟ | D28: No | E28: =IF(D28='Support sheet '!$B$35,2,IF(D28='Support sheet '!$B$36,1,IF(D28='Support sheet '!$B$37,0))) -> 0
B29: Cross- Border movement mapping "رسم خريطة الحركة عبر الحدود " | C29: Structured border with administrative controls Have travel routes (e.g. origin, destination and transit pathways) and the potential for international traffic dispersal through links to major roadways, railways, airports and ports of entry been assessed? "حدود منظمة مع ضوابط إدارية هل تم تقييم طرق السفر (على سبيل المثال، المنشأ والوجهة ومسارات العبور) وإمكانية تشتت حركة المرور الدولية من خلال الروابط مع الطرق الرئيسية والسكك الحديدية والمطارات وموانئ الدخول؟ | D29: No | E29: =IF(D29='Support sheet '!$B$35,2,IF(D29='Support sheet '!$B$36,1,IF(D29='Support sheet '!$B$37,0))) -> 0
C30: An open/porous border Have the critical access points from one country to another along the border been identified in order to understand the movement dynamics of travellers, goods and cargo? حدود مفتوحة/مسامية هل تم تحديد نقاط الوصول الحرجة من بلد إلى آخر على طول الحدود من أجل فهم ديناميكيات حركة المسافرين والسلع والبضائع؟ | D30: No | E30: =IF(D30='Support sheet '!$B$35,2,IF(D30='Support sheet '!$B$36,1,IF(D30='Support sheet '!$B$37,0))) -> 0
C31: An open/porous border Have the critical points of congregation where cross-border travellers may interact with other travellers and/or adjacent border communities been identified? "حدود مفتوحة/مسامية هل تم تحديد نقاط التجمع الحرجة حيث قد يتفاعل المسافرون عبر الحدود مع مسافرين آخرين و/أو مجتمعات حدودية مجاورة؟ | D31: No | E31: =IF(D31='Support sheet '!$B$35,2,IF(D31='Support sheet '!$B$36,1,IF(D31='Support sheet '!$B$37,0))) -> 0
C32: An open/porous border • Are the points of access and of congregation prioritized on the basis of estimates of traveller volume? "حدود مفتوحة/مسامية • هل يتم تحديد نقاط الوصول ونقاط التجمع على أساس تقديرات حجم المسافرين؟ | D32: No | E32: =IF(D32='Support sheet '!$B$35,2,IF(D32='Support sheet '!$B$36,1,IF(D32='Support sheet '!$B$37,0))) -> 0
B33: Assessment and care of travellers تقييم ورعاية المسافرين | C33: Has adequate space been identified to conduct private interviews with ill travellers at the ground crossing? "هل تم تحديد مساحة كافية لإجراء مقابلات خاصة مع المسافرين المرضى عند معبر الحدود البري؟ | D33: Yes / Completed | E33: =IF(D33='Support sheet '!$B$35,2,IF(D33='Support sheet '!$B$36,1,IF(D33='Support sheet '!$B$37,0))) -> 2
C34: Have isolation and quarantine facilities been identified? هل تم تحديد مرافق العزل والحجر الصحي؟ | D34: No | E34: =IF(D34='Support sheet '!$B$35,2,IF(D34='Support sheet '!$B$36,1,IF(D34='Support sheet '!$B$37,0))) -> 0
C35: Are there language or cultural barriers that may occur when assessing travellers? هل هناك حواجز لغوية أو ثقافية قد تحدث عند تقييم المسافرين؟ | D35: Yes / Completed | E35: =IF(D35='Support sheet '!$B$35,2,IF(D35='Support sheet '!$B$36,1,IF(D35='Support sheet '!$B$37,0))) -> 2
C36: Are translation services available? هل تتوفر خدمات الترجمة؟ | D36: No | E36: =IF(D36='Support sheet '!$B$35,2,IF(D36='Support sheet '!$B$36,1,IF(D36='Support sheet '!$B$37,0))) -> 0
C37: Have shelter, sanitation, water, waste disposal, food, privacy, safety, communications and transportation been accounted for when undertaking observation or isolation of suspect or affected travellers at ground crossings? هل تم أخذ المأوى والصرف الصحي والمياه والتخلص من النفايات والغذاء والخصوصية والسلامة والاتصالات والنقل في الاعتبار عند إجراء المراقبة أو عزل المسافرين المشتبه بهم أو المتأثرين عند معبر الحدود البري؟ | D37: Yes / Completed | E37: =IF(D37='Support sheet '!$B$35,2,IF(D37='Support sheet '!$B$36,1,IF(D37='Support sheet '!$B$37,0))) -> 2
C38: Has access to qualified laboratories been identified and established? هل تم تحديد وتأسيس إمكانية الوصول إلى المختبرات المؤهلة؟ | D38: Yes / Completed | E38: =IF(D38='Support sheet '!$B$35,2,IF(D38='Support sheet '!$B$36,1,IF(D38='Support sheet '!$B$37,0))) -> 2
B39: Health care facilities مؤسسات الرعاية الصحية | C39: Have the type and proximity of the health-care facilities relative to the ground crossing been determined? هل تم تحديد نوع وقرب مرافق الرعاية الصحية بالنسبة لمعبر الحدود البري؟ | D39: Yes / Completed | E39: =IF(D39='Support sheet '!$B$35,2,IF(D39='Support sheet '!$B$36,1,IF(D39='Support sheet '!$B$37,0))) -> 2
C40: Do travellers and ground crossing staff have access to medical professionals? ل يمكن للمسافرين وموظفي معبر الحدود البري الوصول إلى المتخصصين الطبيين؟ " | D40: Yes / Completed | E40: =IF(D40='Support sheet '!$B$35,2,IF(D40='Support sheet '!$B$36,1,IF(D40='Support sheet '!$B$37,0))) -> 2
C41: Are accessible health-care facilities able to respond to a communicable disease event? هل المرافق الصحية التي يمكن الوصول إليها قادرة على الاستجابة لحدث مرض معد؟ | D41: No | E41: =IF(D41='Support sheet '!$B$35,2,IF(D41='Support sheet '!$B$36,1,IF(D41='Support sheet '!$B$37,0))) -> 0
B42: Transportation الترحيل | C42: Have sample transport procedures been established (cross-border transport)?هل تم وضع إجراءات نقل العينات (النقل عبر الحدود)؟ | D42: Yes / Completed | E42: =IF(D42='Support sheet '!$B$35,2,IF(D42='Support sheet '!$B$36,1,IF(D42='Support sheet '!$B$37,0))) -> 2
C43: Are there means available to transport ill/suspect travellers from a ground crossing to a health care facility? هل تتوفر وسائل لنقل المسافرين المرضى/المشتبه بهم من معبر حدودي إلى مرفق رعاية صحية؟ | D43: Yes / Completed | E43: =IF(D43='Support sheet '!$B$35,2,IF(D43='Support sheet '!$B$36,1,IF(D43='Support sheet '!$B$37,0))) -> 2
B44: Trained staff الكادر المدرب | C44: Are sufficient numbers of trained staff available for routine functions at ground crossings? هل يتوفر عدد كاف من الموظفين المدربين لأداء الوظائف الروتينية عند المعابر الأرضية؟ | D44: No | E44: =IF(D44='Support sheet '!$B$35,2,IF(D44='Support sheet '!$B$36,1,IF(D44='Support sheet '!$B$37,0))) -> 0
...

Sheet 7- Likelihood Assessment 
C4: Exposure: For each possible hazard (biological, chemical, physical or radiological), determine the likelihood of occurrence. Determine the likelihood of occurrence of a hazard by evaluating its frequency and seasonality, and by identifying the possible negative health consequences for populations at ground crossings and in adjacent border communities. "التعرض: بالنسبة لكل خطر محتمل (بيولوجي أو كيميائي أو فيزيائي أو إشعاعي)، حدد احتمالية حدوثه. حدد احتمالية حدوث الخطر من خلال تقييم تواتر حدوثه وموسميته، ومن خلال تحديد العواقب الصحية السلبية المحتملة على السكان عند المعابر البرية وفي المجتمعات الحدودية المجاورة.
C5: Guiding factors to take into consideration when determining exposure: العوامل التوجيهية التي يجب أخذها في الاعتبار عند تحديد التعرض:
C6: • Are there any interactions at ground crossings and in the border region that facilitate the introduction/spread of diseases to the bordering countries? هل هناك أي تفاعلات عند المعابر البرية وفي منطقة الحدود تسهل إدخال/انتشار الأمراض إلى البلدان المجاورة؟ • Is the hazard highly infectious? هل الخطر شديد العدوي • Is there any past evidence of local spread within the border region? هل هناك أي دليل سابق على انتشار محلي داخل منطقة الحدود؟ • Is there an index case that is associated with a history of travelling to bordering countries within the previous month, or of close contact with a traveller/mobile population at the ground crossing, or participation in an international gathering in the bordering countries? هل هناك حالة مؤشر مرتبطة بتاريخ السفر إلى البلدان المجاورة خلال الشهر السابق، أو اتصال وثيق مع مسافر/سكان متنقلين عند المعبر البري، أو المشاركة في تجمع دولي في البلدان المجاورة؟ • Is there any past evidence of an event caused by environmental contamination associated with this specific hazard (biological, zoonotic, chemical or radiological) that has the potential to spread across borders? هل هناك أي دليل سابق على حدوث حدث ناتج عن تلوث بيئي مرتبط بهذا الخطر المحدد (بيولوجي، حيواني المنشأ، كيميائي أو إشعاعي) لديه القدرة على الانتشار عبر الحدود؟ • Is the event at a ground crossing or in a border region with intense international traffic and limited capacity for sanitary control or environmental disinfection and decontamination? هل الحدث عند معبر بري أو في منطقة حدودية ذات حركة مرور دولية مكثفة وقدرة محدودة على التحكم الصحي أو التطهير البيئي وإزالة التلوث؟ The assessment team should use the information collected to answer, for each possible hazard, the five questions that are below. Each question should be answered by either YES or NO. YES scores 1 and NO scores 0. يجب على فريق التقييم استخدام المعلومات التي تم جمعها للإجابة، لكل خطر محتمل، على الأسئلة الخمسة أدناه. يجب الإجابة على كل سؤال إما بنعم أو لا. تحصل الإجابة بنعم على 1 وتحصل الإجابة بلا على 0. Click on the drop-down tab in the cell in front of the question to choose the answer. Following this action, the score will appear in the next cell on the same line. When all five questions have been answered, the total likelihood score for the identified hazard will appear in the cell next to the "TOTAL SCORE" cell. This score will also appear on line 103 and the likelihood level will appear on line 104 under the column assigned to the identified hazard. انقر فوق علامة التبويب المنسدلة في الخلية أمام السؤال لاختيار الإجابة. وبعد هذا الإجراء، ستظهر النتيجة في الخلية التالية على نفس السطر. وعندما تتم الإجابة على الأسئلة الخمسة، ستظهر درجة الاحتمالية الإجمالية للخطر المحدد في الخلية بجوار خلية ""الدرجة الإجمالية"". وستظهر هذه النتيجة أيضًا في السطر 103 وسيظهر مستوى الاحتمالية في السطر 104 أسفل العمود المخصص للخطر المحدد. The assigned score from 1 to 5 would be as follows: ستكون النتيجة المخصصة من 1 إلى 5 على النحو التالي: 1. Very unlikely غير محتمل للغاية 2 2. Unlikely غير محتمل 3 3. Likely محتمل 4 4. Very likely محتمل جدا 5 5. Almost certain شيه مؤكد
C9: HAZARD 1 | D9: ='3-Hazard Assessment'!B14 -> Dengue
C10: QUESTIONS | D10: YES / NO | E10: Score
C11: Are there any interactions at ground crossings and in the border region that facilitate the introduction/spread of diseases to the bordering countries? هل هناك أي تفاعلات عند المعابر البرية وفي منطقة الحدود تسهل إدخال/انتشار الأمراض إلى البلدان المجاورة؟ | D11: YES | E11: =IF(D11="YES",1,0) -> 1
C12: Is the hazard highly infectious? هل الخطر معدي للغاية؟ | D12: NO | E12: =IF(D12="YES",1,0) -> 0
C13: Is there any past evidence of local spread within the border region? هل هناك أي دليل سابق على انتشار محلي داخل منطقة الحدود؟ | D13: YES | E13: =IF(D13="YES",1,0) -> 1
C14: Is there any past evidence of an event caused by environmental contamination associated with this specific hazard (biological, zoonotic, chemical or radiological) that has the potential to spread across borders? هل هناك أي دليل سابق على وقوع حدث ناتج عن تلوث بيئي مرتبط بهذا الخطر المحدد (البيولوجي أو الحيواني أو الكيميائي أو الإشعاعي) والذي يحتمل أن ينتشر عبر الحدود؟ | D14: NO | E14: =IF(D14="YES",1,0) -> 0
C15: Is the event at a ground crossing or in a border region with intense international traffic and limited capacity for sanitary control or environmental disinfection and decontamination? هل وقع الحدث عند معبر بري أو في منطقة حدودية ذات حركة مرور دولية مكثفة وقدرة محدودة على التحكم الصحي أو تطهير البيئة وإزالة التلوث؟ | D15: NO | E15: =IF(D15="YES",1,0) -> 0
C16: TOTAL SCORE | E16: =SUM(E11:E15) -> 2
C18: HAZARD 2 | D18: ='3-Hazard Assessment'!C14 -> Cholera
C19: QUESTIONS | D19: YES / NO | E19: Score
C20: Are there any interactions at ground crossings and in the border region that facilitate the introduction/spread of diseases to the bordering countries? | D20: YES | E20: =IF(D20="YES",1,0) -> 1
C21: Is the hazard highly infectious? | D21: YES | E21: =IF(D21="YES",1,0) -> 1
C22: Is there any past evidence of local spread within the border region? | D22: YES | E22: =IF(D22="YES",1,0) -> 1
C23: Is there any past evidence of an event caused by environmental contamination associated with this specific hazard (biological, zoonotic, chemical or radiological) that has the potential to spread across borders? | D23: YES | E23: =IF(D23="YES",1,0) -> 1
C24: Is the event at a ground crossing or in a border region with intense international traffic and limited capacity for sanitary control or environmental disinfection and decontamination? | D24: YES | E24: =IF(D24="YES",1,0) -> 1
C25: TOTAL SCORE | E25: =SUM(E20:E24) -> 5
C27: HAZARD 3 | D27: ='3-Hazard Assessment'!D14 -> Malaria
C28: QUESTIONS | D28: YES / NO | E28: Score
C29: Are there any interactions at ground crossings and in the border region that facilitate the introduction/spread of diseases to the bordering countries? | D29: YES | E29: =IF(D29="YES",1,0) -> 1
C30: Is the hazard highly infectious? | D30: YES | E30: =IF(D30="YES",1,0) -> 1
C31: Is there any past evidence of local spread within the border region? | D31: NO | E31: =IF(D31="YES",1,0) -> 0
C32: Is there any past evidence of an event caused by environmental contamination associated with this specific hazard (biological, zoonotic, chemical or radiological) that has the potential to spread across borders? | D32: NO | E32: =IF(D32="YES",1,0) -> 0
C33: Is the event at a ground crossing or in a border region with intense international traffic and limited capacity for sanitary control or environmental disinfection and decontamination? | D33: NO | E33: =IF(D33="YES",1,0) -> 0
C34: TOTAL SCORE | E34: =SUM(E29:E33) -> 2
C36: HAZARD 4 | D36: ='3-Hazard Assessment'!E14 -> VHF
C37: QUESTIONS | D37: YES / NO | E37: Score
C38: Are there any interactions at ground crossings and in the border region that facilitate the introduction/spread of diseases to the bordering countries? | D38: YES | E38: =IF(D38="YES",1,0) -> 1
C39: Is the hazard highly infectious? | D39: YES | E39: =IF(D39="YES",1,0) -> 1
C40: Is there any past evidence of local spread within the border region? | D40: NO | E40: =IF(D40="YES",1,0) -> 0
C41: Is there any past evidence of an event caused by environmental contamination associated with this specific hazard (biological, zoonotic, chemical or radiological) that has the potential to spread across borders? | D41: NO | E41: =IF(D41="YES",1,0) -> 0
C42: Is the event at a ground crossing or in a border region with intense international traffic and limited capacity for sanitary control or environmental disinfection and decontamination? | D42: NO | E42: =IF(D42="YES",1,0) -> 0
C43: TOTAL SCORE | E43: =SUM(E38:E42) -> 2
C45: HAZARD 5 | D45: ='3-Hazard Assessment'!F14 -> Covid-19
C46: QUESTIONS | D46: YES / NO | E46: Score
C47: Are there any interactions at ground crossings and in the border region that facilitate the introduction/spread of diseases to the bordering countries? | D47: YES | E47: =IF(D47="YES",1,0) -> 1
C48: Is the hazard highly infectious? | D48: YES | E48: =IF(D48="YES",1,0) -> 1
C49: Is there any past evidence of local spread within the border region? | D49: YES | E49: =IF(D49="YES",1,0) -> 1
...

Sheet 8-Scorecard
C2: The scale of the impact of an individual hazard is determined by an aggregation of the scores given for vulnerability, severity and coping capacity. يتم تحديد حجم تأثير الخطر الفردي من خلال تجميع الدرجات المعطاة للضعف والشدة والقدرة على التكيف Impact = (vulnerability + severity + coping capacity)/3 التأثير = (الضعف + الشدة + القدرة على التكيف) / 3 1. Very low منخفض جدا 2. Low منخفض 3. Moderate متوسط 4. High عالي 5. Very high عالي جدا
D7: Hazard 1 | E7: Hazard 2 | F7: Hazard 3 | G7: Hazard 4 | H7: Hazard 5 | I7: Hazard 6 | J7: Hazard 7 | K7: Hazard 8 | L7: Hazard 9 | M7: Hazard 10
C8: Hazard name اسم الخطر | D8: ='3-Hazard Assessment'!B14 -> Dengue | E8: ='3-Hazard Assessment'!C14 -> Cholera | F8: ='3-Hazard Assessment'!D14 -> Malaria | G8: ='3-Hazard Assessment'!E14 -> VHF | H8: ='3-Hazard Assessment'!F14 -> Covid-19 | I8: ='3-Hazard Assessment'!G14 -> Influenza | J8: ='3-Hazard Assessment'!H14 -> Mass Casualities | K8: ='3-Hazard Assessment'!I14 -> Chemical | ... M8: ='3-Hazard Assessment'!K14 -> Physical
C9: Exposure التعرض | D9: ='4- Vulnerabilty Assessment'!D103 -> 5 | E9: ='4- Vulnerabilty Assessment'!E103 -> 5 | F9: ='4- Vulnerabilty Assessment'!F103 -> 5 | G9: ='4- Vulnerabilty Assessment'!G103 -> 5 | H9: ='4- Vulnerabilty Assessment'!H103 -> 4 | I9: ='4- Vulnerabilty Assessment'!I103 -> 5 | J9: ='4- Vulnerabilty Assessment'!J103 -> 2 | K9: ='4- Vulnerabilty Assessment'!K103 -> 4 | ... M9: ='4- Vulnerabilty Assessment'!M103 -> 4
C10: Severtiy شدة | D10: ='5- Severity Assessment '!C81 -> 3 | E10: ='5- Severity Assessment '!D81 -> 5 | F10: ='5- Severity Assessment '!E81 -> 2 | G10: ='5- Severity Assessment '!F81 -> 3 | H10: ='5- Severity Assessment '!G81 -> 2 | I10: ='5- Severity Assessment '!H81 -> 1 | J10: ='5- Severity Assessment '!I81 -> 3 | K10: ='5- Severity Assessment '!J81 -> 2 | ... M10: ='5- Severity Assessment '!L81 -> 4
C11: Coping capacities قدرات التأقلم | D11: =' 6-Capacity Assessment'!$E$96 -> 3 | E11: =' 6-Capacity Assessment'!$E$96 -> 3 | F11: =' 6-Capacity Assessment'!$E$96 -> 3 | G11: =' 6-Capacity Assessment'!$E$96 -> 3 | H11: =' 6-Capacity Assessment'!$E$96 -> 3 | I11: =' 6-Capacity Assessment'!$E$96 -> 3 | J11: =' 6-Capacity Assessment'!$E$96 -> 3 | K11: =' 6-Capacity Assessment'!$E$96 -> 3 | ... M11: =' 6-Capacity Assessment'!$E$96 -> 3
C12: Impact تأثير | D12: =(D9+D10+D11)/3 -> 3.6666667 | E12: =(E9+E10+E11)/3 -> 4.3333333 | F12: =(F9+F10+F11)/3 -> 3.3333333 | G12: =(G9+G10+G11)/3 -> 3.6666667 | H12: =(H9+H10+H11)/3 -> 3 | I12: =(I9+I10+I11)/3 -> 3 | J12: =(J9+J10+J11)/3 -> 2.6666667 | K12: =(K9+K10+K11)/3 -> 3 | ... M12: =(M9+M10+M11)/3 -> 3.6666667
C13: Rounding line | D13: =ROUND(D12,0) -> 4 | E13: =ROUND(E12,0) -> 4 | F13: =ROUND(F12,0) -> 3 | G13: =ROUND(G12,0) -> 4 | H13: =ROUND(H12,0) -> 3 | I13: =ROUND(I12,0) -> 3 | J13: =ROUND(J12,0) -> 3 | K13: =ROUND(K12,0) -> 3 | ... M13: =ROUND(M12,0) -> 4
C14: Impact level مستوي التأثير | D14: =IF(D13=1, "Very low",IF(D13=2,"Low",IF(D13=3,"Moderate",IF(D13=4,"High",IF(D13=5,"Very high"))))) -> High | E14: =IF(E13=1, "Very low",IF(E13=2,"Low",IF(E13=3,"Moderate",IF(E13=4,"High",IF(E13=5,"Very high"))))) -> High | F14: =IF(F13=1, "Very low",IF(F13=2,"Low",IF(F13=3,"Moderate",IF(F13=4,"High",IF(F13=5,"Very high"))))) -> Moderate | G14: =IF(G13=1, "Very low",IF(G13=2,"Low",IF(G13=3,"Moderate",IF(G13=4,"High",IF(G13=5,"Very high"))))) -> High | H14: =IF(H13=1, "Very low",IF(H13=2,"Low",IF(H13=3,"Moderate",IF(H13=4,"High",IF(H13=5,"Very high"))))) -> Moderate | I14: =IF(I13=1, "Very low",IF(I13=2,"Low",IF(I13=3,"Moderate",IF(I13=4,"High",IF(I13=5,"Very high"))))) -> Moderate | J14: =IF(J13=1, "Very low",IF(J13=2,"Low",IF(J13=3,"Moderate",IF(J13=4,"High",IF(J13=5,"Very high"))))) -> Moderate | K14: =IF(K13=1, "Very low",IF(K13=2,"Low",IF(K13=3,"Moderate",IF(K13=4,"High",IF(K13=5,"Very high"))))) -> Moderate | ... M14: =IF(M13=1, "Very low",IF(M13=2,"Low",IF(M13=3,"Moderate",IF(M13=4,"High",IF(M13=5,"Very high"))))) -> High
C17: Likelihood score درجة الاحتمالية | D17: ='7- Likelihood Assessment '!D103 -> 2 | E17: ='7- Likelihood Assessment '!E103 -> 5 | F17: ='7- Likelihood Assessment '!F103 -> 2 | G17: ='7- Likelihood Assessment '!G103 -> 2 | H17: ='7- Likelihood Assessment '!H103 -> 5 | I17: ='7- Likelihood Assessment '!I103 -> 1 | J17: ='7- Likelihood Assessment '!J103 -> 1 | K17: ='7- Likelihood Assessment '!K103 -> 2 | ... M17: ='7- Likelihood Assessment '!M103 -> 3
C18: Likelihood level مستوي الاحتمالية | D18: =IF(D17=1,"Very Unlikely",IF(D17=2,"Unlikely",IF(D17=3,"Likely",IF(D17=4,"Very Likely",IF(D17=5,"Almost certain"))))) -> Unlikely | E18: =IF(E17=1,"Very Unlikely",IF(E17=2,"Unlikely",IF(E17=3,"Likely",IF(E17=4,"Very Likely",IF(E17=5,"Almost certain"))))) -> Almost certain | F18: =IF(F17=1,"Very Unlikely",IF(F17=2,"Unlikely",IF(F17=3,"Likely",IF(F17=4,"Very Likely",IF(F17=5,"Almost certain"))))) -> Unlikely | G18: =IF(G17=1,"Very Unlikely",IF(G17=2,"Unlikely",IF(G17=3,"Likely",IF(G17=4,"Very Likely",IF(G17=5,"Almost certain"))))) -> Unlikely | H18: =IF(H17=1,"Very Unlikely",IF(H17=2,"Unlikely",IF(H17=3,"Likely",IF(H17=4,"Very Likely",IF(H17=5,"Almost certain"))))) -> Almost certain | I18: =IF(I17=1,"Very Unlikely",IF(I17=2,"Unlikely",IF(I17=3,"Likely",IF(I17=4,"Very Likely",IF(I17=5,"Almost certain"))))) -> Very Unlikely | J18: =IF(J17=1,"Very Unlikely",IF(J17=2,"Unlikely",IF(J17=3,"Likely",IF(J17=4,"Very Likely",IF(J17=5,"Almost certain"))))) -> Very Unlikely | K18: =IF(K17=1,"Very Unlikely",IF(K17=2,"Unlikely",IF(K17=3,"Likely",IF(K17=4,"Very Likely",IF(K17=5,"Almost certain"))))) -> Unlikely | ... M18: =IF(M17=1,"Very Unlikely",IF(M17=2,"Unlikely",IF(M17=3,"Likely",IF(M17=4,"Very Likely",IF(M17=5,"Almost certain"))))) -> Likely
C20: RISK MATRIX GUIDE
C21: Likelihood of hazard occurring | D21: Almost certain شيه مؤكد
D22: Very likely من المحتمل جدا
D23: Likely محتمل
D24: Unlikely غير محتمل
D25: Very unlikely غير محتمل جدا
E26: Very low | F26: Low | G26: Moderate | H26: High | I26: Very high
E27: Consequences of hazard occurring (impact) عواقب وقوع الخطر (التأثير)
C29: RISK MATRIX HAZARD 1 | D29: =D8 -> Dengue
C30: Likelihood of hazard occurring | D30: Almost certain
D31: Very likely
D32: Likely
D33: Unlikely
D34: Very unlikely
E35: Very low | F35: Low | G35: Moderate | H35: High | I35: Very high
E36: Consequences of hazard occurring (impact)
C39: RISK MATRIX HAZARD 2 | D39: =E8 -> Cholera
C40: Likelihood of hazard occurring | D40: Almost certain
D41: Very likely
D42: Likely
D43: Unlikely
D44: Very unlikely
E45: Very low | F45: Low | G45: Moderate | H45: High | I45: Very high
E46: Consequences of hazard occurring (impact)
C49: RISK MATRIX HAZARD 3 | D49: =F8 -> Malaria
C50: Likelihood of hazard occurring | D50: Almost certain
D51: Very likely
D52: Likely
D53: Unlikely
...

Sheet 9-Mitigation Measures
C3: يجب أن يقرر فريق التقييم إجراءات تخفيف المخاطر المطلوبة، بالإضافة إلى الحد الأدنى وإجراءات الاستعداد الإضافية. ينبغي لفريق التقييم أن يعطي الأولوية لأنشطة تنمية القدرات التي يحركها المستوى العام للمخاطر (الاحتمال × التأثير)، على النحو الذي تحدده عملية توصيف المخاطر باتباع دليل تدابير التخفيف أدناه
C5: دليل تدابير التخفيف
C6: احتمالية وتأثير كل خطر | D6: إجراءات تخفيف المخاطر | E6: Capacities/examplesالقدرات/الأمثلة
D7: Minimum preparedness actions (ground crossing capacity development activities)إجراءات الاستعداد الدنيا (أنشطة تنمية قدرات المعابر البريه) | E7: Ongoing monitoring of the hazards to determine that the impact or likelihood does not increase.المراقبة المستمرة للمخاطر لتحديد أن التأثير أو الاحتمالية لا تزيد.
